<?xml version="1.0" encoding="UTF-8"?>
<testng-results ignored="0" total="4" passed="2" failed="2" skipped="0">
  <reporter-output>
  </reporter-output>
  <suite started-at="2024-12-22T18:50:02 IST" name="Default suite" finished-at="2024-12-22T18:50:11 IST" duration-ms="8885">
    <groups>
    </groups>
    <test started-at="2024-12-22T18:50:02 IST" name="Default test" finished-at="2024-12-22T18:50:11 IST" duration-ms="8885">
      <class name="api.testcases.UserTest">
        <test-method is-config="true" signature="genrerateTestData()[pri:0, instance:api.testcases.UserTest@408d971b]" started-at="2024-12-22T18:50:02 IST" name="genrerateTestData" finished-at="2024-12-22T18:50:02 IST" duration-ms="423" status="PASS">
          <reporter-output>
          </reporter-output>
        </test-method> <!-- genrerateTestData -->
        <test-method signature="testCreateUser()[pri:1, instance:api.testcases.UserTest@408d971b]" started-at="2024-12-22T18:50:02 IST" name="testCreateUser" finished-at="2024-12-22T18:50:07 IST" duration-ms="4630" status="FAIL">
          <exception class="java.lang.AssertionError">
            <message>
              <![CDATA[expected [201] but found [200]]]>
            </message>
            <full-stacktrace>
              <![CDATA[java.lang.AssertionError: expected [201] but found [200]
at org.testng.Assert.fail(Assert.java:111)
at org.testng.Assert.failNotEquals(Assert.java:1578)
at org.testng.Assert.assertEqualsImpl(Assert.java:150)
at org.testng.Assert.assertEquals(Assert.java:132)
at org.testng.Assert.assertEquals(Assert.java:1419)
at org.testng.Assert.assertEquals(Assert.java:1383)
at org.testng.Assert.assertEquals(Assert.java:1429)
at api.testcases.UserTest.testCreateUser(UserTest.java:43)
at java.base/jdk.internal.reflect.DirectMethodHandleAccessor.invoke(DirectMethodHandleAccessor.java:103)
at java.base/java.lang.reflect.Method.invoke(Method.java:580)
at org.testng.internal.invokers.MethodInvocationHelper.invokeMethod(MethodInvocationHelper.java:141)
at org.testng.internal.invokers.TestInvoker.invokeMethod(TestInvoker.java:686)
at org.testng.internal.invokers.TestInvoker.invokeTestMethod(TestInvoker.java:230)
at org.testng.internal.invokers.MethodRunner.runInSequence(MethodRunner.java:63)
at org.testng.internal.invokers.TestInvoker$MethodInvocationAgent.invoke(TestInvoker.java:992)
at org.testng.internal.invokers.TestInvoker.invokeTestMethods(TestInvoker.java:203)
at org.testng.internal.invokers.TestMethodWorker.invokeTestMethods(TestMethodWorker.java:154)
at org.testng.internal.invokers.TestMethodWorker.run(TestMethodWorker.java:134)
at java.base/java.util.ArrayList.forEach(ArrayList.java:1596)
at org.testng.TestRunner.privateRun(TestRunner.java:739)
at org.testng.TestRunner.run(TestRunner.java:614)
at org.testng.SuiteRunner.runTest(SuiteRunner.java:421)
at org.testng.SuiteRunner.runSequentially(SuiteRunner.java:413)
at org.testng.SuiteRunner.privateRun(SuiteRunner.java:373)
at org.testng.SuiteRunner.run(SuiteRunner.java:312)
at org.testng.SuiteRunnerWorker.runSuite(SuiteRunnerWorker.java:52)
at org.testng.SuiteRunnerWorker.run(SuiteRunnerWorker.java:95)
at org.testng.TestNG.runSuitesSequentially(TestNG.java:1274)
at org.testng.TestNG.runSuitesLocally(TestNG.java:1208)
at org.testng.TestNG.runSuites(TestNG.java:1112)
at org.testng.TestNG.run(TestNG.java:1079)
at org.testng.remote.AbstractRemoteTestNG.run(AbstractRemoteTestNG.java:115)
at org.testng.remote.RemoteTestNG.initAndRun(RemoteTestNG.java:293)
at org.testng.remote.RemoteTestNG.main(RemoteTestNG.java:91)
]]>
            </full-stacktrace>
          </exception> <!-- java.lang.AssertionError -->
          <reporter-output>
          </reporter-output>
        </test-method> <!-- testCreateUser -->
        <test-method signature="testGetUser()[pri:2, instance:api.testcases.UserTest@408d971b]" started-at="2024-12-22T18:50:07 IST" name="testGetUser" finished-at="2024-12-22T18:50:08 IST" duration-ms="1272" status="PASS">
          <reporter-output>
          </reporter-output>
        </test-method> <!-- testGetUser -->
        <test-method signature="testUpdateUser()[pri:3, instance:api.testcases.UserTest@408d971b]" started-at="2024-12-22T18:50:08 IST" name="testUpdateUser" finished-at="2024-12-22T18:50:09 IST" duration-ms="1239" status="FAIL">
          <exception class="java.lang.AssertionError">
            <message>
              <![CDATA[expected [201] but found [200]]]>
            </message>
            <full-stacktrace>
              <![CDATA[java.lang.AssertionError: expected [201] but found [200]
at org.testng.Assert.fail(Assert.java:111)
at org.testng.Assert.failNotEquals(Assert.java:1578)
at org.testng.Assert.assertEqualsImpl(Assert.java:150)
at org.testng.Assert.assertEquals(Assert.java:132)
at org.testng.Assert.assertEquals(Assert.java:1419)
at org.testng.Assert.assertEquals(Assert.java:1383)
at org.testng.Assert.assertEquals(Assert.java:1429)
at api.testcases.UserTest.testUpdateUser(UserTest.java:62)
at java.base/jdk.internal.reflect.DirectMethodHandleAccessor.invoke(DirectMethodHandleAccessor.java:103)
at java.base/java.lang.reflect.Method.invoke(Method.java:580)
at org.testng.internal.invokers.MethodInvocationHelper.invokeMethod(MethodInvocationHelper.java:141)
at org.testng.internal.invokers.TestInvoker.invokeMethod(TestInvoker.java:686)
at org.testng.internal.invokers.TestInvoker.invokeTestMethod(TestInvoker.java:230)
at org.testng.internal.invokers.MethodRunner.runInSequence(MethodRunner.java:63)
at org.testng.internal.invokers.TestInvoker$MethodInvocationAgent.invoke(TestInvoker.java:992)
at org.testng.internal.invokers.TestInvoker.invokeTestMethods(TestInvoker.java:203)
at org.testng.internal.invokers.TestMethodWorker.invokeTestMethods(TestMethodWorker.java:154)
at org.testng.internal.invokers.TestMethodWorker.run(TestMethodWorker.java:134)
at java.base/java.util.ArrayList.forEach(ArrayList.java:1596)
at org.testng.TestRunner.privateRun(TestRunner.java:739)
at org.testng.TestRunner.run(TestRunner.java:614)
at org.testng.SuiteRunner.runTest(SuiteRunner.java:421)
at org.testng.SuiteRunner.runSequentially(SuiteRunner.java:413)
at org.testng.SuiteRunner.privateRun(SuiteRunner.java:373)
at org.testng.SuiteRunner.run(SuiteRunner.java:312)
at org.testng.SuiteRunnerWorker.runSuite(SuiteRunnerWorker.java:52)
at org.testng.SuiteRunnerWorker.run(SuiteRunnerWorker.java:95)
at org.testng.TestNG.runSuitesSequentially(TestNG.java:1274)
at org.testng.TestNG.runSuitesLocally(TestNG.java:1208)
at org.testng.TestNG.runSuites(TestNG.java:1112)
at org.testng.TestNG.run(TestNG.java:1079)
at org.testng.remote.AbstractRemoteTestNG.run(AbstractRemoteTestNG.java:115)
at org.testng.remote.RemoteTestNG.initAndRun(RemoteTestNG.java:293)
at org.testng.remote.RemoteTestNG.main(RemoteTestNG.java:91)
]]>
            </full-stacktrace>
          </exception> <!-- java.lang.AssertionError -->
          <reporter-output>
          </reporter-output>
        </test-method> <!-- testUpdateUser -->
        <test-method signature="testDeletUser()[pri:4, instance:api.testcases.UserTest@408d971b]" started-at="2024-12-22T18:50:09 IST" name="testDeletUser" finished-at="2024-12-22T18:50:11 IST" duration-ms="1232" status="PASS">
          <reporter-output>
          </reporter-output>
        </test-method> <!-- testDeletUser -->
      </class> <!-- api.testcases.UserTest -->
    </test> <!-- Default test -->
  </suite> <!-- Default suite -->
</testng-results>
